[2025-04-18T06:47:20.768+0000] {local_task_job_runner.py:123} INFO - ::group::Pre task execution logs
[2025-04-18T06:47:20.782+0000] {taskinstance.py:2614} INFO - Dependencies all met for dep_context=non-requeueable deps ti=<TaskInstance: image_processing_pipeline.upload_processed_images scheduled__2025-04-18T06:35:00+00:00 [queued]>
[2025-04-18T06:47:20.788+0000] {taskinstance.py:2614} INFO - Dependencies all met for dep_context=requeueable deps ti=<TaskInstance: image_processing_pipeline.upload_processed_images scheduled__2025-04-18T06:35:00+00:00 [queued]>
[2025-04-18T06:47:20.788+0000] {taskinstance.py:2867} INFO - Starting attempt 1 of 2
[2025-04-18T06:47:20.802+0000] {taskinstance.py:2890} INFO - Executing <Task(PythonOperator): upload_processed_images> on 2025-04-18 06:35:00+00:00
[2025-04-18T06:47:20.810+0000] {standard_task_runner.py:104} INFO - Running: ['***', 'tasks', 'run', 'image_processing_pipeline', 'upload_processed_images', 'scheduled__2025-04-18T06:35:00+00:00', '--job-id', '55', '--raw', '--subdir', 'DAGS_FOLDER/image_processing_dag.py', '--cfg-path', '/tmp/tmp36g9xm13']
[2025-04-18T06:47:20.811+0000] {standard_task_runner.py:105} INFO - Job 55: Subtask upload_processed_images
[2025-04-18T06:47:20.812+0000] {logging_mixin.py:190} WARNING - /home/***/.local/lib/python3.12/site-packages/***/task/task_runner/standard_task_runner.py:70 DeprecationWarning: This process (pid=335) is multi-threaded, use of fork() may lead to deadlocks in the child.
[2025-04-18T06:47:20.813+0000] {standard_task_runner.py:72} INFO - Started process 336 to run task
[2025-04-18T06:47:20.838+0000] {task_command.py:467} INFO - Running <TaskInstance: image_processing_pipeline.upload_processed_images scheduled__2025-04-18T06:35:00+00:00 [running]> on host 96ec7c07bc54
[2025-04-18T06:47:20.888+0000] {taskinstance.py:3134} INFO - Exporting env vars: AIRFLOW_CTX_DAG_OWNER='***' AIRFLOW_CTX_DAG_ID='image_processing_pipeline' AIRFLOW_CTX_TASK_ID='upload_processed_images' AIRFLOW_CTX_EXECUTION_DATE='2025-04-18T06:35:00+00:00' AIRFLOW_CTX_TRY_NUMBER='1' AIRFLOW_CTX_DAG_RUN_ID='scheduled__2025-04-18T06:35:00+00:00'
[2025-04-18T06:47:20.889+0000] {taskinstance.py:732} INFO - ::endgroup::
[2025-04-18T06:47:20.905+0000] {s3_operations.py:30} INFO - Uploading /tmp/***_image_processing/Dario-Nessi_Sir-no-photos-please-copy.jpg to processed-images-***/processed/Dario-Nessi_Sir-no-photos-please-copy.jpg
[2025-04-18T06:47:21.016+0000] {base.py:84} INFO - Retrieving connection 'aws_default'
[2025-04-18T06:47:22.044+0000] {taskinstance.py:3313} ERROR - Task failed with exception
Traceback (most recent call last):
  File "/home/airflow/.local/lib/python3.12/site-packages/boto3/s3/transfer.py", line 372, in upload_file
    future.result()
  File "/home/airflow/.local/lib/python3.12/site-packages/s3transfer/futures.py", line 103, in result
    return self._coordinator.result()
           ^^^^^^^^^^^^^^^^^^^^^^^^^^
  File "/home/airflow/.local/lib/python3.12/site-packages/s3transfer/futures.py", line 264, in result
    raise self._exception
  File "/home/airflow/.local/lib/python3.12/site-packages/s3transfer/tasks.py", line 135, in __call__
    return self._execute_main(kwargs)
           ^^^^^^^^^^^^^^^^^^^^^^^^^^
  File "/home/airflow/.local/lib/python3.12/site-packages/s3transfer/tasks.py", line 158, in _execute_main
    return_value = self._main(**kwargs)
                   ^^^^^^^^^^^^^^^^^^^^
  File "/home/airflow/.local/lib/python3.12/site-packages/s3transfer/upload.py", line 796, in _main
    client.put_object(Bucket=bucket, Key=key, Body=body, **extra_args)
  File "/home/airflow/.local/lib/python3.12/site-packages/botocore/client.py", line 570, in _api_call
    return self._make_api_call(operation_name, kwargs)
           ^^^^^^^^^^^^^^^^^^^^^^^^^^^^^^^^^^^^^^^^^^^
  File "/home/airflow/.local/lib/python3.12/site-packages/botocore/context.py", line 124, in wrapper
    return func(*args, **kwargs)
           ^^^^^^^^^^^^^^^^^^^^^
  File "/home/airflow/.local/lib/python3.12/site-packages/botocore/client.py", line 1031, in _make_api_call
    raise error_class(parsed_response, operation_name)
botocore.exceptions.ClientError: An error occurred (IncompleteBody) when calling the PutObject operation: You did not provide the number of bytes specified by the Content-Length HTTP header

During handling of the above exception, another exception occurred:

Traceback (most recent call last):
  File "/home/airflow/.local/lib/python3.12/site-packages/airflow/models/taskinstance.py", line 768, in _execute_task
    result = _execute_callable(context=context, **execute_callable_kwargs)
             ^^^^^^^^^^^^^^^^^^^^^^^^^^^^^^^^^^^^^^^^^^^^^^^^^^^^^^^^^^^^^
  File "/home/airflow/.local/lib/python3.12/site-packages/airflow/models/taskinstance.py", line 734, in _execute_callable
    return ExecutionCallableRunner(
           ^^^^^^^^^^^^^^^^^^^^^^^^
  File "/home/airflow/.local/lib/python3.12/site-packages/airflow/utils/operator_helpers.py", line 252, in run
    return self.func(*args, **kwargs)
           ^^^^^^^^^^^^^^^^^^^^^^^^^^
  File "/home/airflow/.local/lib/python3.12/site-packages/airflow/models/baseoperator.py", line 424, in wrapper
    return func(self, *args, **kwargs)
           ^^^^^^^^^^^^^^^^^^^^^^^^^^^
  File "/home/airflow/.local/lib/python3.12/site-packages/airflow/operators/python.py", line 238, in execute
    return_value = self.execute_callable()
                   ^^^^^^^^^^^^^^^^^^^^^^^
  File "/home/airflow/.local/lib/python3.12/site-packages/airflow/operators/python.py", line 256, in execute_callable
    return runner.run(*self.op_args, **self.op_kwargs)
           ^^^^^^^^^^^^^^^^^^^^^^^^^^^^^^^^^^^^^^^^^^^
  File "/home/airflow/.local/lib/python3.12/site-packages/airflow/utils/operator_helpers.py", line 252, in run
    return self.func(*args, **kwargs)
           ^^^^^^^^^^^^^^^^^^^^^^^^^^
  File "/opt/airflow/dags/image_processing_dag.py", line 151, in upload_processed_images
    s3_url = upload_to_s3(local_path, PROCESSED_BUCKET, processed_key)
             ^^^^^^^^^^^^^^^^^^^^^^^^^^^^^^^^^^^^^^^^^^^^^^^^^^^^^^^^^
  File "/opt/airflow/dags/utils/s3_operations.py", line 32, in upload_to_s3
    s3_client.upload_file(local_path, bucket, key)
  File "/home/airflow/.local/lib/python3.12/site-packages/botocore/context.py", line 124, in wrapper
    return func(*args, **kwargs)
           ^^^^^^^^^^^^^^^^^^^^^
  File "/home/airflow/.local/lib/python3.12/site-packages/boto3/s3/inject.py", line 175, in upload_file
    return transfer.upload_file(
           ^^^^^^^^^^^^^^^^^^^^^
  File "/home/airflow/.local/lib/python3.12/site-packages/boto3/s3/transfer.py", line 378, in upload_file
    raise S3UploadFailedError(
boto3.exceptions.S3UploadFailedError: Failed to upload /tmp/***_image_processing/Dario-Nessi_Sir-no-photos-please-copy.jpg to processed-images-***/processed/Dario-Nessi_Sir-no-photos-please-copy.jpg: An error occurred (IncompleteBody) when calling the PutObject operation: You did not provide the number of bytes specified by the Content-Length HTTP header
[2025-04-18T06:47:22.077+0000] {taskinstance.py:1226} INFO - Marking task as UP_FOR_RETRY. dag_id=image_processing_pipeline, task_id=upload_processed_images, run_id=scheduled__2025-04-18T06:35:00+00:00, execution_date=20250418T063500, start_date=20250418T064720, end_date=20250418T064722
[2025-04-18T06:47:22.101+0000] {taskinstance.py:341} INFO - ::group::Post task execution logs
[2025-04-18T06:47:22.101+0000] {standard_task_runner.py:124} ERROR - Failed to execute job 55 for task upload_processed_images (Failed to upload /tmp/***_image_processing/Dario-Nessi_Sir-no-photos-please-copy.jpg to processed-images-***/processed/Dario-Nessi_Sir-no-photos-please-copy.jpg: An error occurred (IncompleteBody) when calling the PutObject operation: You did not provide the number of bytes specified by the Content-Length HTTP header; 336)
Traceback (most recent call last):
  File "/home/airflow/.local/lib/python3.12/site-packages/boto3/s3/transfer.py", line 372, in upload_file
    future.result()
  File "/home/airflow/.local/lib/python3.12/site-packages/s3transfer/futures.py", line 103, in result
    return self._coordinator.result()
           ^^^^^^^^^^^^^^^^^^^^^^^^^^
  File "/home/airflow/.local/lib/python3.12/site-packages/s3transfer/futures.py", line 264, in result
    raise self._exception
  File "/home/airflow/.local/lib/python3.12/site-packages/s3transfer/tasks.py", line 135, in __call__
    return self._execute_main(kwargs)
           ^^^^^^^^^^^^^^^^^^^^^^^^^^
  File "/home/airflow/.local/lib/python3.12/site-packages/s3transfer/tasks.py", line 158, in _execute_main
    return_value = self._main(**kwargs)
                   ^^^^^^^^^^^^^^^^^^^^
  File "/home/airflow/.local/lib/python3.12/site-packages/s3transfer/upload.py", line 796, in _main
    client.put_object(Bucket=bucket, Key=key, Body=body, **extra_args)
  File "/home/airflow/.local/lib/python3.12/site-packages/botocore/client.py", line 570, in _api_call
    return self._make_api_call(operation_name, kwargs)
           ^^^^^^^^^^^^^^^^^^^^^^^^^^^^^^^^^^^^^^^^^^^
  File "/home/airflow/.local/lib/python3.12/site-packages/botocore/context.py", line 124, in wrapper
    return func(*args, **kwargs)
           ^^^^^^^^^^^^^^^^^^^^^
  File "/home/airflow/.local/lib/python3.12/site-packages/botocore/client.py", line 1031, in _make_api_call
    raise error_class(parsed_response, operation_name)
botocore.exceptions.ClientError: An error occurred (IncompleteBody) when calling the PutObject operation: You did not provide the number of bytes specified by the Content-Length HTTP header

During handling of the above exception, another exception occurred:

Traceback (most recent call last):
  File "/home/airflow/.local/lib/python3.12/site-packages/airflow/task/task_runner/standard_task_runner.py", line 117, in _start_by_fork
    ret = args.func(args, dag=self.dag)
          ^^^^^^^^^^^^^^^^^^^^^^^^^^^^^
  File "/home/airflow/.local/lib/python3.12/site-packages/airflow/cli/cli_config.py", line 49, in command
    return func(*args, **kwargs)
           ^^^^^^^^^^^^^^^^^^^^^
  File "/home/airflow/.local/lib/python3.12/site-packages/airflow/utils/cli.py", line 116, in wrapper
    return f(*args, **kwargs)
           ^^^^^^^^^^^^^^^^^^
  File "/home/airflow/.local/lib/python3.12/site-packages/airflow/cli/commands/task_command.py", line 483, in task_run
    task_return_code = _run_task_by_selected_method(args, _dag, ti)
                       ^^^^^^^^^^^^^^^^^^^^^^^^^^^^^^^^^^^^^^^^^^^^
  File "/home/airflow/.local/lib/python3.12/site-packages/airflow/cli/commands/task_command.py", line 256, in _run_task_by_selected_method
    return _run_raw_task(args, ti)
           ^^^^^^^^^^^^^^^^^^^^^^^
  File "/home/airflow/.local/lib/python3.12/site-packages/airflow/cli/commands/task_command.py", line 341, in _run_raw_task
    return ti._run_raw_task(
           ^^^^^^^^^^^^^^^^^
  File "/home/airflow/.local/lib/python3.12/site-packages/airflow/utils/session.py", line 97, in wrapper
    return func(*args, session=session, **kwargs)
           ^^^^^^^^^^^^^^^^^^^^^^^^^^^^^^^^^^^^^^
  File "/home/airflow/.local/lib/python3.12/site-packages/airflow/models/taskinstance.py", line 3006, in _run_raw_task
    return _run_raw_task(
           ^^^^^^^^^^^^^^
  File "/home/airflow/.local/lib/python3.12/site-packages/airflow/models/taskinstance.py", line 274, in _run_raw_task
    TaskInstance._execute_task_with_callbacks(
  File "/home/airflow/.local/lib/python3.12/site-packages/airflow/models/taskinstance.py", line 3161, in _execute_task_with_callbacks
    result = self._execute_task(context, task_orig)
             ^^^^^^^^^^^^^^^^^^^^^^^^^^^^^^^^^^^^^^
  File "/home/airflow/.local/lib/python3.12/site-packages/airflow/models/taskinstance.py", line 3185, in _execute_task
    return _execute_task(self, context, task_orig)
           ^^^^^^^^^^^^^^^^^^^^^^^^^^^^^^^^^^^^^^^
  File "/home/airflow/.local/lib/python3.12/site-packages/airflow/models/taskinstance.py", line 768, in _execute_task
    result = _execute_callable(context=context, **execute_callable_kwargs)
             ^^^^^^^^^^^^^^^^^^^^^^^^^^^^^^^^^^^^^^^^^^^^^^^^^^^^^^^^^^^^^
  File "/home/airflow/.local/lib/python3.12/site-packages/airflow/models/taskinstance.py", line 734, in _execute_callable
    return ExecutionCallableRunner(
           ^^^^^^^^^^^^^^^^^^^^^^^^
  File "/home/airflow/.local/lib/python3.12/site-packages/airflow/utils/operator_helpers.py", line 252, in run
    return self.func(*args, **kwargs)
           ^^^^^^^^^^^^^^^^^^^^^^^^^^
  File "/home/airflow/.local/lib/python3.12/site-packages/airflow/models/baseoperator.py", line 424, in wrapper
    return func(self, *args, **kwargs)
           ^^^^^^^^^^^^^^^^^^^^^^^^^^^
  File "/home/airflow/.local/lib/python3.12/site-packages/airflow/operators/python.py", line 238, in execute
    return_value = self.execute_callable()
                   ^^^^^^^^^^^^^^^^^^^^^^^
  File "/home/airflow/.local/lib/python3.12/site-packages/airflow/operators/python.py", line 256, in execute_callable
    return runner.run(*self.op_args, **self.op_kwargs)
           ^^^^^^^^^^^^^^^^^^^^^^^^^^^^^^^^^^^^^^^^^^^
  File "/home/airflow/.local/lib/python3.12/site-packages/airflow/utils/operator_helpers.py", line 252, in run
    return self.func(*args, **kwargs)
           ^^^^^^^^^^^^^^^^^^^^^^^^^^
  File "/opt/airflow/dags/image_processing_dag.py", line 151, in upload_processed_images
    s3_url = upload_to_s3(local_path, PROCESSED_BUCKET, processed_key)
             ^^^^^^^^^^^^^^^^^^^^^^^^^^^^^^^^^^^^^^^^^^^^^^^^^^^^^^^^^
  File "/opt/airflow/dags/utils/s3_operations.py", line 32, in upload_to_s3
    s3_client.upload_file(local_path, bucket, key)
  File "/home/airflow/.local/lib/python3.12/site-packages/botocore/context.py", line 124, in wrapper
    return func(*args, **kwargs)
           ^^^^^^^^^^^^^^^^^^^^^
  File "/home/airflow/.local/lib/python3.12/site-packages/boto3/s3/inject.py", line 175, in upload_file
    return transfer.upload_file(
           ^^^^^^^^^^^^^^^^^^^^^
  File "/home/airflow/.local/lib/python3.12/site-packages/boto3/s3/transfer.py", line 378, in upload_file
    raise S3UploadFailedError(
boto3.exceptions.S3UploadFailedError: Failed to upload /tmp/***_image_processing/Dario-Nessi_Sir-no-photos-please-copy.jpg to processed-images-***/processed/Dario-Nessi_Sir-no-photos-please-copy.jpg: An error occurred (IncompleteBody) when calling the PutObject operation: You did not provide the number of bytes specified by the Content-Length HTTP header
[2025-04-18T06:47:22.149+0000] {local_task_job_runner.py:266} INFO - Task exited with return code 1
[2025-04-18T06:47:22.174+0000] {taskinstance.py:3901} INFO - 0 downstream tasks scheduled from follow-on schedule check
[2025-04-18T06:47:22.175+0000] {local_task_job_runner.py:245} INFO - ::endgroup::
